<robot name="onshape">
    <link name="drone">
        <visual><origin xyz="5.5511151231257827021e-17 -5.5511151231257827021e-17 0" rpy="0 -0 0" /><geometry>
            <mesh filename= "package://arm-drone/urdf/arm-drone/drone.stl" />
        </geometry><material name="drone_material"><color rgba="0.76862745098039220171 0.88627450980392152857 0.95294117647058818044 1.0" /></material></visual><collision><origin xyz="5.5511151231257827021e-17 -5.5511151231257827021e-17 0" rpy="0 -0 0" /><geometry>
                <mesh filename="package://arm-drone/urdf/arm-drone/drone.stl" /></geometry></collision><inertial><origin xyz="0 0 0" /><mass value="0" /><inertia ixx="0" ixy="0" ixz="0" iyy="0" iyz="0" izz="0" /></inertial></link><link name="arm_hinge"><visual><origin xyz="0 3.4694469519536141888e-18 -0.020000000000000003886" rpy="0 -0 0" /><geometry>
                    <mesh filename="package://arm-drone/urdf/arm-drone/arm_hinge.stl" /></geometry><material name="arm_hinge_material"><color rgba="0.61568627450980395466 0.81176470588235294379 0.92941176470588238168 1.0" /></material></visual><collision><origin xyz="0 3.4694469519536141888e-18 -0.020000000000000003886" rpy="0 -0 0" /><geometry>
                        <mesh filename="package://arm-drone/urdf/arm-drone/arm_hinge.stl" /></geometry></collision><inertial><origin xyz="0 0 0" /><mass value="0" /><inertia ixx="0" ixy="0" ixz="0" iyy="0" iyz="0" izz="0" /></inertial></link><link name="arm"><visual><origin xyz="0 0 -0.020000000000000000416" rpy="-1.570796326794896558 -1.570796326794896558 0" /><geometry>
                            <mesh filename="package://arm-drone/urdf/arm-drone/arm.stl" /></geometry><material name="arm_material"><color rgba="0.64705882352941179736 0.64705882352941179736 0.64705882352941179736 1.0" /></material></visual><collision><origin xyz="0 0 -0.020000000000000000416" rpy="-1.570796326794896558 -1.570796326794896558 0" /><geometry>
                                <mesh filename="package://arm-drone/urdf/arm-drone/arm.stl" /></geometry></collision><inertial><origin xyz="0 0 0" /><mass value="0" /><inertia ixx="0" ixy="0" ixz="0" iyy="0" iyz="0" izz="0" /></inertial></link><link name="roller_center"><visual><origin xyz="0 0 0" rpy="-1.2197507505365855551e-33 -1.2087183088652343291e-34 4.3140830754331010859e-32" /><geometry>
                                    <mesh filename="package://arm-drone/urdf/arm-drone/cube.stl" /></geometry><material name="cube_material"><color rgba="0.61568627450980395466 0.81176470588235294379 0.92941176470588238168 1.0" /></material></visual><collision><origin xyz="0 0 0" rpy="-1.2197507505365855551e-33 -1.2087183088652343291e-34 4.3140830754331010859e-32" /><geometry>
                                        <mesh filename="package://arm-drone/urdf/arm-drone/cube.stl" /></geometry></collision><inertial><origin xyz="0 0 0" /><mass value="0" /><inertia ixx="0" ixy="0" ixz="0" iyy="0" iyz="0" izz="0" /></inertial></link><joint name="arm_roller_center" type="fixed"><origin xyz="3.4694469519536141888e-18 -0.29999999999999993339 -0.020000000000000000416" rpy="-3.7823242981197238136e-17 2.1448854157642213953e-17 -1.570796326794896336" /><parent link="arm" /><child link="roller_center" /><axis xyz="0 0 1" /><limit effort="1" velocity="20" /><joint_properties friction="0.0" /></joint><joint name="arm" type="revolute"><origin xyz="0.020000000000000003886 2.7755575615628913511e-17 -0.019999999999999986539" rpy="1.570796326794896558 -5.967448757360180906e-16 1.570796326794896558" /><parent link="arm_hinge" /><child link="arm" /><axis xyz="0 0 1" /><limit effort="1" velocity="20" lower="0" upper="1.3089969389957472057" /><joint_properties friction="0.0" /></joint><joint name="arm_bracket" type="fixed"><origin xyz="5.5511151231257827021e-17 -0.029699999999999063954 -1.3877787807814456755e-17" rpy="0 -0 0" /><parent link="drone" /><child link="arm_hinge" /><axis xyz="0 0 1" /><limit effort="1" velocity="20" /><joint_properties friction="0.0" /></joint><link name="cg"><visual><origin xyz="0 0 0" rpy="0 -0 0" /><geometry>
                                            <mesh filename="package://arm-drone/urdf/arm-drone/cube.stl" /></geometry><material name="cube_material"><color rgba="0.61568627450980395466 0.81176470588235294379 0.92941176470588238168 1.0" /></material></visual><collision><origin xyz="0 0 0" rpy="0 -0 0" /><geometry>
                                                <mesh filename="package://arm-drone/urdf/arm-drone/cube.stl" /></geometry></collision><inertial><origin xyz="0 0 0" /><mass value="0" /><inertia ixx="0" ixy="0" ixz="0" iyy="0" iyz="0" izz="0" /></inertial></link><joint name="cg" type="fixed"><origin xyz="-3.7955031092379710916e-18 3.1403516550117630373e-18 0.014000000000000000291" rpy="0 -0 0" /><parent link="drone" /><child link="cg" /><axis xyz="0 0 1" /><limit effort="1" velocity="20" /><joint_properties friction="0.0" /></joint></robot>